Workbook

Sheet novatel_oem615_nominal
A1: CCSDS_STREAMID | B1: CCSDS_SEQUENCE | C1: CCSDS_LENGTH | D1: CCSDS_SECONDS | E1: CCSDS_SUBSECS | F1: CCSDS_SPARE | G1: GPS_WEEKS | H1: GPS_SECONDS | I1: GPS_FRAC_SECS | J1: ECEF_X | K1: ECEF_Y | L1: ECEF_Z | M1: VEL_X | N1: VEL_Y | O1: VEL_Z | P1: LAT | Q1: LON | R1: ALT
A2: 2161 | B2: 49333 | C2: 83 | D2: 61 | E2: 39976 | F2: 0 | G2: 341 | H2: 150279 | I2: 0.984 | J2: -2616000 | K2: -6243000 | L2: 354700 | M2: 4029 | N2: -1342 | O2: 6029 | P2: 2.6376984 | Q2: -113.00284 | R2: 400004.56
A3: 2161 | B3: 49334 | C3: 83 | D3: 61 | E3: 56360 | F3: 0 | G3: 341 | H3: 150280 | I3: 0.234 | J3: -2615000 | K3: -6243000 | L3: 356200 | M3: 4030 | N3: -1340 | O3: 6029 | P3: 2.6376984 | Q3: -113.00284 | R3: 400004.56
A4: 2161 | B4: 49335 | C4: 83 | D4: 62 | E4: 7208 | F4: 0 | G4: 341 | H4: 150280 | I4: 0.484 | J4: -2614000 | K4: -6243000 | L4: 357700 | M4: 4030 | N4: -1338 | O4: 6029 | P4: 2.6376984 | Q4: -113.00284 | R4: 400004.56
A5: 2161 | B5: 49336 | C5: 83 | D5: 62 | E5: 23592 | F5: 0 | G5: 341 | H5: 150280 | I5: 0.484 | J5: -2614000 | K5: -6243000 | L5: 357700 | M5: 4030 | N5: -1338 | O5: 6029 | P5: 3.0573797 | Q5: -112.71042 | R5: 399992.47
A6: 2161 | B6: 49337 | C6: 83 | D6: 62 | E6: 56360 | F6: 0 | G6: 341 | H6: 150281 | I6: 0.234 | J6: -2611000 | K6: -6244000 | L6: 362200 | M6: 4033 | N6: -1333 | O6: 6029 | P6: 3.0573797 | Q6: -112.71042 | R6: 399992.47
A7: 2161 | B7: 49338 | C7: 83 | D7: 63 | E7: 7208 | F7: 0 | G7: 341 | H7: 150281 | I7: 0.484 | J7: -2610000 | K7: -6245000 | L7: 363700 | M7: 4034 | N7: -1331 | O7: 6029 | P7: 3.0573797 | Q7: -112.71042 | R7: 399992.47
A8: 2161 | B8: 49339 | C8: 83 | D8: 63 | E8: 23592 | F8: 0 | G8: 341 | H8: 150281 | I8: 0.734 | J8: -2609000 | K8: -6245000 | L8: 365200 | M8: 4034 | N8: -1329 | O8: 6028 | P8: 3.0573797 | Q8: -112.71042 | R8: 399992.47
A9: 2161 | B9: 49340 | C9: 83 | D9: 63 | E9: 39976 | F9: 0 | G9: 341 | H9: 150281 | I9: 0.984 | J9: -2608000 | K9: -6245000 | L9: 366700 | M9: 4035 | N9: -1327 | O9: 6028 | P9: 3.0573797 | Q9: -112.71042 | R9: 399992.47
A10: 2161 | B10: 49341 | C10: 83 | D10: 63 | E10: 56360 | F10: 0 | G10: 341 | H10: 150282 | I10: 0.234 | J10: -2607000 | K10: -6246000 | L10: 368200 | M10: 4036 | N10: -1325 | O10: 6028 | P10: 3.0573797 | Q10: -112.71042 | R10: 399992.47
A11: 2161 | B11: 49342 | C11: 83 | D11: 64 | E11: 7208 | F11: 0 | G11: 341 | H11: 150282 | I11: 0.484 | J11: -2606000 | K11: -6246000 | L11: 369700 | M11: 4037 | N11: -1323 | O11: 6028 | P11: 3.0573797 | Q11: -112.71042 | R11: 399992.47
A12: 2161 | B12: 49343 | C12: 83 | D12: 64 | E12: 23592 | F12: 0 | G12: 341 | H12: 150282 | I12: 0.734 | J12: -2605000 | K12: -6246000 | L12: 371200 | M12: 4037 | N12: -1322 | O12: 6028 | P12: 3.0573797 | Q12: -112.71042 | R12: 399992.47
A13: 2161 | B13: 49344 | C13: 83 | D13: 64 | E13: 39976 | F13: 0 | G13: 341 | H13: 150282 | I13: 0.984 | J13: -2604000 | K13: -6247000 | L13: 372600 | M13: 4038 | N13: -1320 | O13: 6028 | P13: 3.0573797 | Q13: -112.71042 | R13: 399992.47
... A2179: 2161 | B2179: 51561 | C2179: 83 | D2179: 646 | E2179: 12451 | F2179: 0 | G2179: 341 | H2179: 150864 | I2179: 0.734 | J2179: 97250 | K2179: -5770000 | L2179: 3524000 | M2179: 5076 | N2179: 2903 | O2179: 4518 | P2179: 31.129728 | Q2179: -89.522995 | R2179: 390000.19

Sheet generic_imu_nominal
A1: CCSDS_STREAMID | B1: CCSDS_SEQUENCE | C1: CCSDS_LENGTH | D1: CCSDS_SECONDS | E1: CCSDS_SUBSECS | F1: CCSDS_SPARE | G1: X_LINEAR_ACCELERATION | H1: X_ANGULAR_RATE | I1: Y_LINEAR_ACCELERATION | J1: Y_ANGULAR_RATE | K1: Z_LINEAR_ACCELERATION | L1: Z_ANGULAR_RATE
A2: 2342 | B2: 49203 | C2: 33 | D2: 62 | E2: 1310 | F2: 0 | G2: -0.0014966354 | H2: 0.0043004751 | I2: 0.0014317408 | J2: 0.003489852 | K2: -0.0039344653 | L2: -0.030532479
A3: 2342 | B3: 49204 | C3: 33 | D3: 63 | E3: 1310 | F3: 0 | G3: -0.0013470277 | H3: -0.0059992075 | I3: -0.00011082739 | J3: 0.0038713217 | K3: -0.0031888112 | L3: -0.029245019
A4: 2342 | B4: 49205 | C4: 33 | D4: 64 | E4: 1310 | F4: 0 | G4: -0.0013666973 | H4: 0.0039190054 | I4: 0.0014186278 | J4: 0.0029653311 | K4: -0.0033157691 | L4: -0.028386712
A5: 2342 | B5: 49206 | C5: 33 | D5: 65 | E5: 1310 | F5: 0 | G5: -0.0012701377 | H5: -0.0061184168 | I5: -7.8640878e-05 | J5: 0.0037282705 | K5: -0.0026529655 | L5: -0.028434396
A6: 2342 | B6: 49207 | C6: 33 | D6: 66 | E6: 1310 | F6: 0 | G6: -0.0013297424 | H6: 0.0059217215 | I6: 0.001716651 | J6: 0.0037759542 | K6: -0.0022941455 | L6: -0.027266145
A7: 2342 | B7: 49208 | C7: 33 | D7: 67 | E7: 1310 | F7: 0 | G7: -0.0011467561 | H7: -0.0073105097 | I7: -0.00020142645 | J7: 0.0032514334 | K7: -0.0021105632 | L7: -0.026288629
A8: 2342 | B8: 49209 | C8: 33 | D8: 68 | E8: 1310 | F8: 0 | G8: -0.0013196096 | H8: 0.0063508749 | I8: 0.0018227473 | J8: 0.0023454428 | K8: -0.0024294481 | L8: -0.02643168
A9: 2342 | B9: 49210 | C9: 33 | D9: 69 | E9: 1310 | F9: 0 | G9: -0.0010889396 | H9: -0.0091224909 | I9: -0.00043209642 | J9: 0.0032514334 | K9: -0.0015675649 | L9: -0.025120378
A10: 2342 | B10: 49211 | C10: 33 | D10: 70 | E10: 1310 | F10: 0 | G10: -0.0011866912 | H10: 0.0066369772 | I10: 0.0018179789 | J10: 0.0033468008 | K10: -0.0013106689 | L10: -0.024262071
A11: 2342 | B11: 49212 | C11: 33 | D11: 71 | E11: 1310 | F11: 0 | G11: -0.00098463148 | H11: -0.0076681376 | I11: -0.00020321459 | J11: 0.0029176474 | K11: -0.001286231 | L11: -0.024309754
A12: 2342 | B12: 49213 | C12: 33 | D12: 72 | E12: 1310 | F12: 0 | G12: -0.0012266263 | H12: 0.0080674887 | I12: 0.0020301715 | J12: 0.0020116568 | K12: -0.0014692172 | L12: -0.02309382
A13: 2342 | B13: 49214 | C13: 33 | D13: 73 | E13: 1310 | F13: 0 | G13: -0.00085648149 | H13: -0.0087887049 | I13: -0.00034388155 | J13: 0.0029653311 | K13: -0.00071879476 | L13: -0.022116303
... A584: 2342 | B584: 49787 | C584: 33 | D584: 646 | E584: 1310 | F584: 0 | G584: -0.00043924898 | H584: 0.0074476004 | I584: 0.00071529299 | J584: 0.00077188015 | K584: 0.00041250139 | L584: 0.00029504299

Sheet Nominal
A1: Novatel timestamp | C1: ECEF_X | D1: ECEF_Y | E1: ECEF_Z | F1: VEL_X | G1: VEL_Y | H1: VEL_Z | I1: LAT | J1: LON | K1: ALT | M1: X_LINEAR_ACCELERATION | N1: X_ANGULAR_RATE | O1: Y_LINEAR_ACCELERATION | P1: Y_ANGULAR_RATE | Q1: Z_LINEAR_ACCELERATION | R1: Z_ANGULAR_RATE | AJ1: time_jump | AK1: pos_jump | AL1: velocity_mismatch | AM1: imu_mismatch | AN1: stale_gnss | AO1: heading_mismatch | AP1: frozen_position
A2: {=novatel_oem615_nominal!G1100:G2179*604800+novatel_oem615_nominal!H1100:H2179+novatel_oem615_nominal!I1100:I2179} -> 2.0638737e+08 | C2: {=novatel_oem615_nominal!J1100:J2179} -> -1327000 | D2: {=novatel_oem615_nominal!K1100:K2179} -> -6315000 | E2: {=novatel_oem615_nominal!L1100:L2179} -> 2060000 | F2: {=novatel_oem615_nominal!M1100:M2179} -> 4765 | G2: {=novatel_oem615_nominal!N1100:N2179} -> 845.9 | H2: {=novatel_oem615_nominal!O1100:O2179} -> 5570 | I2: {=novatel_oem615_nominal!P1100:P2179} -> 17.674484 | J2: {=novatel_oem615_nominal!Q1100:Q2179} -> -101.97807 | K2: {=novatel_oem615_nominal!R1100:R2179} -> 397258.62 | M2: {=generic_imu_nominal!G293:G584} -> 0.00027064234 | N2: {=generic_imu_nominal!H293:H584} -> -0.0076442957 | O2: {=generic_imu_nominal!I293:I584} -> -0.0007706508 | P2: {=generic_imu_nominal!J293:J584} -> 0.00081956387 | Q2: {=generic_imu_nominal!K293:K584} -> 0.00028256327 | R2: {=generic_imu_nominal!L293:L584} -> 0.00010430813 | AJ2: 1 | AK2: =NA() -> #N/A | AL2: 3 | AM2: 4 | AN2: 5 | AO2: =NA() -> #N/A | AP2: =NA() -> #N/A
A3: 2.0638737e+08 | C3: -1326000 | D3: -6314000 | E3: 2061000 | F3: 4765 | G3: 847.8 | H3: 5569 | I3: 17.674484 | J3: -101.97807 | K3: 397258.62 | M3: -0.00057455152 | N3: 0.0089257956 | O3: 0.00087145716 | P3: 0.00053346157 | Q3: 0.00035289675 | R3: 0.00015199184 | AJ3: 1 | AK3: =NA() -> #N/A | AL3: 3 | AM3: =NA() -> #N/A | AN3: =NA() -> #N/A | AO3: =NA() -> #N/A | AP3: =NA() -> #N/A
A4: 2.0638737e+08 | C4: -1325000 | D4: -6314000 | E4: 2063000 | F4: 4766 | G4: 849.6 | H4: 5569 | I4: 17.674484 | J4: -101.97807 | K4: 397258.62 | M4: 0.00026468188 | N4: -0.0073820353 | O4: -0.00074382871 | P4: 0.00077188015 | Q4: 0.00026229769 | R4: 5.6624413e-05 | AJ4: =NA() -> #N/A | AK4: =NA() -> #N/A | AL4: =NA() -> #N/A | AM4: =NA() -> #N/A | AN4: =NA() -> #N/A | AO4: =NA() -> #N/A | AP4: =NA() -> #N/A
A5: 2.0638738e+08 | C5: -1323000 | D5: -6314000 | E5: 2065000 | F5: 4767 | G5: 853.3 | H5: 5567 | I5: 17.674484 | J5: -101.97807 | K5: 397258.62 | M5: -0.00045772642 | N5: 0.0075429678 | O5: 0.00073675066 | P5: 0.00053346157 | Q5: 0.00033143908 | R5: 0.00010430813 | AJ5: =NA() -> #N/A | AK5: =NA() -> #N/A | AL5: =NA() -> #N/A | AM5: =NA() -> #N/A | AN5: =NA() -> #N/A | AO5: =NA() -> #N/A | AP5: =NA() -> #N/A
A6: 2.0638738e+08 | C6: -1321000 | D6: -6314000 | E6: 2067000 | F6: 4767 | G6: 855.2 | H6: 5567 | I6: 17.674484 | J6: -101.97807 | K6: 397258.62 | M6: 0.00028017908 | N6: -0.008764863 | O6: -0.0008797273 | P6: 0.00081956387 | Q6: 0.00028017908 | R6: 8.9406967e-06 | AJ6: =NA() -> #N/A | AK6: =NA() -> #N/A | AL6: =NA() -> #N/A | AM6: =NA() -> #N/A | AN6: =NA() -> #N/A | AO6: =NA() -> #N/A | AP6: =NA() -> #N/A
A7: 2.0638738e+08 | C7: -1321000 | D7: -6314000 | E7: 2067000 | F7: 4767 | G7: 855.2 | H7: 5567 | I7: 17.884064 | J7: -101.81049 | K7: 397179.91 | M7: -0.00047918409 | N7: 0.0078290701 | O7: 0.00076893717 | P7: 0.00058114529 | Q7: 0.00036362559 | R7: 5.6624413e-05 | AJ7: 1 | AK7: =NA() -> #N/A | AL7: 3 | AM7: =NA() -> #N/A | AN7: =NA() -> #N/A | AO7: =NA() -> #N/A | AP7: =NA() -> #N/A
A8: 2.0638738e+08 | C8: -1319000 | D8: -6313000 | E8: 2069000 | F8: 4768 | G8: 858.9 | H8: 5565 | I8: 17.884064 | J8: -101.81049 | K8: 397179.91 | M8: 0.00027898699 | N8: -0.0084787607 | O8: -0.00085052103 | P8: 0.00086724758 | Q8: 0.00030402094 | R8: -1.4901161e-05 | AJ8: =NA() -> #N/A | AK8: =NA() -> #N/A | AL8: =NA() -> #N/A | AM8: =NA() -> #N/A | AN8: =NA() -> #N/A | AO8: =NA() -> #N/A | AP8: =NA() -> #N/A
A9: 2.0638738e+08 | C9: -1318000 | D9: -6313000 | E9: 2071000 | F9: 4769 | G9: 860.7 | H9: 5565 | I9: 17.884064 | J9: -101.81049 | K9: 397179.91 | M9: -0.000503622 | N9: 0.0081151724 | O9: 0.00080112368 | P9: 0.000628829 | Q9: 0.00038269907 | R9: 8.9406967e-06 | AJ9: =NA() -> #N/A | AK9: =NA() -> #N/A | AL9: =NA() -> #N/A | AM9: =NA() -> #N/A | AN9: =NA() -> #N/A | AO9: =NA() -> #N/A | AP9: =NA() -> #N/A
A10: 2.0638738e+08 | C10: -1317000 | D10: -6313000 | E10: 2072000 | F10: 4769 | G10: 862.5 | H10: 5564 | I10: 17.884064 | J10: -101.81049 | K10: 397179.91 | M10: 0.0002766028 | N10: -0.0081688166 | O10: -0.00081952661 | P10: 0.00086724758 | Q10: 0.00031474978 | R10: -3.8743019e-05 | AJ10: =NA() -> #N/A | AK10: =NA() -> #N/A | AL10: =NA() -> #N/A | AM10: =NA() -> #N/A | AN10: =NA() -> #N/A | AO10: =NA() -> #N/A | AP10: =NA() -> #N/A
A11: 2.0638738e+08 | C11: -1315000 | D11: -6312000 | E11: 2074000 | F11: 4770 | G11: 864.4 | H11: 5563 | I11: 17.884064 | J11: -101.81049 | K11: 397179.91 | M11: -0.00067111105 | N11: 0.0078290701 | O11: 0.00079158694 | P11: -0.002732873 | Q11: -0.0011628494 | R11: 5.6624413e-05 | AJ11: =NA() -> #N/A | AK11: =NA() -> #N/A | AL11: =NA() -> #N/A | AM11: =NA() -> #N/A | AN11: =NA() -> #N/A | AO11: =NA() -> #N/A | AP11: =NA() -> #N/A
A12: 2.0638738e+08 | C12: -1314000 | D12: -6312000 | E12: 2075000 | F12: 4770 | G12: 866.2 | H12: 5563 | I12: 17.884064 | J12: -101.81049 | K12: 397179.91 | M12: 0.00021580607 | N12: -0.0087887049 | O12: -0.00087615103 | P12: -0.0004440546 | Q12: -0.0002765283 | R12: 8.9406967e-06 | AJ12: =NA() -> #N/A | AK12: =NA() -> #N/A | AL12: =NA() -> #N/A | AM12: =NA() -> #N/A | AN12: =NA() -> #N/A | AO12: =NA() -> #N/A | AP12: =NA() -> #N/A
A13: 2.0638738e+08 | C13: -1313000 | D13: -6312000 | E13: 2076000 | F13: 4770 | G13: 868.1 | H13: 5562 | I13: 17.884064 | J13: -101.81049 | K13: 397179.91 | M13: -0.00048216432 | N13: 0.0076860189 | O13: 0.00075940043 | P13: 0.00034272671 | Q13: 0.0002432242 | R13: 5.6624413e-05 | AJ13: =NA() -> #N/A | AK13: =NA() -> #N/A | AL13: =NA() -> #N/A | AM13: =NA() -> #N/A | AN13: =NA() -> #N/A | AO13: =NA() -> #N/A | AP13: =NA() -> #N/A
A14: 2.0638738e+08 | C14: -1312000 | D14: -6312000 | E14: 2078000 | F14: 4771 | G14: 869.9 | H14: 5561 | I14: 17.884064 | J14: -101.81049 | K14: 397179.91 | M14: 0.00029925257 | N14: -0.0085264444 | O14: -0.00085826963 | P14: 0.0012487173 | Q14: 0.00048998743 | R14: -1.4901161e-05 | AJ14: =NA() -> #N/A | AK14: =NA() -> #N/A | AL14: =NA() -> #N/A | AM14: =NA() -> #N/A | AN14: =NA() -> #N/A | AO14: =NA() -> #N/A | AP14: =NA() -> #N/A
A15: 2.0638738e+08 | C15: -1311000 | D15: -6312000 | E15: 2079000 | F15: 4771 | G15: 871.8 | H15: 5561 | I15: 17.884064 | J15: -101.81049 | K15: 397179.91 | M15: -0.00062163919 | N15: 0.0075429678 | O15: 0.00076178461 | P15: -0.0023037195 | Q15: -0.00097390264 | R15: 5.6624413e-05 | AJ15: =NA() -> #N/A | AK15: =NA() -> #N/A | AL15: =NA() -> #N/A | AM15: =NA() -> #N/A | AN15: =NA() -> #N/A | AO15: =NA() -> #N/A | AP15: =NA() -> #N/A
A16: 2.0638738e+08 | C16: -1310000 | D16: -6311000 | E16: 2081000 | F16: 4772 | G16: 873.6 | H16: 5560 | I16: 17.884064 | J16: -101.81049 | K16: 397179.91 | M16: 0.00022176653 | N16: -0.0090271235 | O16: -0.00090058893 | P16: -0.00034868717 | Q16: -0.00023480505 | R16: 8.9406967e-06 | AJ16: =NA() -> #N/A | AK16: =NA() -> #N/A | AL16: =NA() -> #N/A | AM16: =NA() -> #N/A | AN16: =NA() -> #N/A | AO16: =NA() -> #N/A | AP16: =NA() -> #N/A
A17: 2.0638738e+08 | C17: -1308000 | D17: -6311000 | E17: 2082000 | F17: 4772 | G17: 875.5 | H17: 5559 | I17: 17.884064 | J17: -101.81049 | K17: 397179.91 | M17: -0.00047083944 | N17: 0.0073999166 | O17: 0.00073317438 | P17: 0.00010430813 | Q17: 0.00013235956 | R17: 5.6624413e-05 | AJ17: =NA() -> #N/A | AK17: =NA() -> #N/A | AL17: =NA() -> #N/A | AM17: =NA() -> #N/A | AN17: =NA() -> #N/A | AO17: =NA() -> #N/A | AP17: =NA() -> #N/A
A18: 2.0638738e+08 | C18: -1307000 | D18: -6311000 | E18: 2083000 | F18: 4773 | G18: 877.3 | H18: 5559 | I18: 17.884064 | J18: -101.81049 | K18: 397179.91 | M18: 0.00024560839 | N18: -0.0076442957 | O18: -0.00076588243 | P18: 0.00034272671 | Q18: 8.109957e-05 | R18: 8.9406967e-06 | AJ18: =NA() -> #N/A | AK18: =NA() -> #N/A | AL18: =NA() -> #N/A | AM18: =NA() -> #N/A | AN18: =NA() -> #N/A | AO18: =NA() -> #N/A | AP18: =NA() -> #N/A
A19: 2.0638738e+08 | C19: -1306000 | D19: -6311000 | E19: 2085000 | F19: 4773 | G19: 879.1 | H19: 5558 | I19: 17.884064 | J19: -101.81049 | K19: 397179.91 | M19: -0.00057931989 | N19: 0.0088781118 | O19: 0.00087622553 | P19: 0.00039041042 | Q19: 0.00029210001 | R19: 5.6624413e-05 | AJ19: =NA() -> #N/A | AK19: =NA() -> #N/A | AL19: =NA() -> #N/A | AM19: =NA() -> #N/A | AN19: =NA() -> #N/A | AO19: =NA() -> #N/A | AP19: =NA() -> #N/A
... A22: 2.0638738e+08 | C22: -1302000 | D22: -6310000 | E22: 2089000 | F22: 4774 | G22: 884.6 | H22: 5556 | I22: 17.884064 | J22: -101.81049 | K22: 397179.91 | M22: 0.00027183443 | N22: -0.0087171793 | O22: -0.00087317079 | P22: 0.00067651272 | Q22: 0.0002265349 | R22: -3.8743019e-05 | AJ22: =NA() -> #N/A | AK22: =NA() -> #N/A | AL22: =NA() -> #N/A | AM22: =NA() -> #N/A | AN22: =NA() -> #N/A | AO22: =NA() -> #N/A | AP22: =NA() -> #N/A
A23: 2.0638738e+08 | C23: -1302000 | D23: -6310000 | E23: 2089000 | F23: 4774 | G23: 884.6 | H23: 5556 | I23: 18.08112 | J23: -101.65249 | K23: 397113.28 | M23: -0.00048872083 | N23: 0.0078290701 | O23: 0.00077608973 | P23: 0.00043809414 | Q23: 0.00030044466 | R23: 8.9406967e-06 | AJ23: 1 | AK23: =NA() -> #N/A | AL23: 3 | AM23: =NA() -> #N/A | AN23: =NA() -> #N/A | AO23: =NA() -> #N/A | AP23: =NA() -> #N/A
A24: 2.0638738e+08 | C24: -1300000 | D24: -6310000 | E24: 2092000 | F24: 4775 | G24: 888.4 | H24: 5555 | I24: 18.08112 | J24: -101.65249 | K24: 397113.28 | M24: 0.00027064234 | N24: -0.0084787607 | O24: -0.00084932894 | P24: 0.00072419643 | Q24: 0.00024560839 | R24: -6.2584877e-05 | AJ24: =NA() -> #N/A | AK24: =NA() -> #N/A | AL24: =NA() -> #N/A | AM24: =NA() -> #N/A | AN24: =NA() -> #N/A | AO24: =NA() -> #N/A | AP24: =NA() -> #N/A
A25: 2.0638738e+08 | C25: -1299000 | D25: -6309000 | E25: 2093000 | F25: 4776 | G25: 890.2 | H25: 5554 | I25: 18.08112 | J25: -101.65249 | K25: 397113.28 | M25: -0.00050839037 | N25: 0.0080674887 | O25: 0.00080350786 | P25: 0.00043809414 | Q25: 0.00031713396 | R25: -3.8743019e-05 | AJ25: =NA() -> #N/A | AK25: =NA() -> #N/A | AL25: =NA() -> #N/A | AM25: =NA() -> #N/A | AN25: =NA() -> #N/A | AO25: =NA() -> #N/A | AP25: =NA() -> #N/A
A26: 2.0638738e+08 | C26: -1299000 | D26: -6309000 | E26: 2093000 | F26: 4776 | G26: 890.2 | H26: 5554 | I26: 18.117966 | J26: -101.62287 | K26: 397099.91 | M26: 0.00026945025 | N26: -0.0082403421 | O26: -0.00082429498 | P26: 0.00072419643 | Q26: 0.00025514513 | R26: -8.6426735e-05 | AJ26: 1 | AK26: =NA() -> #N/A | AL26: 3 | AM26: =NA() -> #N/A | AN26: =NA() -> #N/A | AO26: =NA() -> #N/A | AP26: =NA() -> #N/A
A27: 2.0638738e+08 | C27: -1299000 | D27: -6309000 | E27: 2093000 | F27: 4776 | G27: 890.2 | H27: 5554 | I27: 18.130365 | J27: -101.61292 | K27: 397093.56 | M27: -0.00053044409 | N27: 0.0083059072 | O27: 0.000830926 | P27: 0.00043809414 | Q27: 0.00032309443 | R27: -6.2584877e-05 | AJ27: 1 | AK27: =NA() -> #N/A | AL27: 3 | AM27: =NA() -> #N/A | AN27: =NA() -> #N/A | AO27: =NA() -> #N/A | AP27: =NA() -> #N/A
A28: 2.0638738e+08 | C28: -1295000 | D28: -6309000 | E28: 2097000 | F28: 4777 | G28: 895.7 | H28: 5552 | I28: 18.130365 | J28: -101.61292 | K28: 397093.56 | M28: 0.00026587397 | N28: -0.0079780817 | O28: -0.00079866499 | P28: 0.00072419643 | Q28: 0.00025395304 | R28: -0.00011026859 | AJ28: =NA() -> #N/A | AK28: =NA() -> #N/A | AL28: =NA() -> #N/A | AM28: =NA() -> #N/A | AN28: =NA() -> #N/A | AO28: =NA() -> #N/A | AP28: =NA() -> #N/A
A29: 2.0638738e+08 | C29: -1294000 | D29: -6309000 | E29: 2098000 | F29: 4778 | G29: 897.5 | H29: 5551 | I29: 18.130365 | J29: -101.61292 | K29: 397093.56 | M29: -0.00055309385 | N29: 0.0085443258 | O29: 0.00085834414 | P29: 0.00043809414 | Q29: 0.00031951815 | R29: -8.6426735e-05 | AJ29: =NA() -> #N/A | AK29: =NA() -> #N/A | AL29: =NA() -> #N/A | AM29: =NA() -> #N/A | AN29: =NA() -> #N/A | AO29: =NA() -> #N/A | AP29: =NA() -> #N/A
A30: 2.0638738e+08 | C30: -1293000 | D30: -6308000 | E30: 2100000 | F30: 4778 | G30: 899.4 | H30: 5551 | I30: 18.130365 | J30: -101.61292 | K30: 397093.56 | M30: 0.0002611056 | N30: -0.0077396631 | O30: -0.00077422708 | P30: 0.00067651272 | Q30: 0.00024203211 | R30: -0.00013411045 | AJ30: =NA() -> #N/A | AK30: =NA() -> #N/A | AL30: =NA() -> #N/A | AM30: =NA() -> #N/A | AN30: =NA() -> #N/A | AO30: =NA() -> #N/A | AP30: =NA() -> #N/A
A31: 2.0638738e+08 | C31: -1292000 | D31: -6308000 | E31: 2101000 | F31: 4779 | G31: 901.2 | H31: 5550 | I31: 18.130365 | J31: -101.61292 | K31: 397093.56 | M31: -0.00057633966 | N31: 0.0087827444 | O31: 0.00088337809 | P31: 0.00039041042 | Q31: 0.00030402094 | R31: -8.6426735e-05 | AJ31: =NA() -> #N/A | AK31: =NA() -> #N/A | AL31: =NA() -> #N/A | AM31: =NA() -> #N/A | AN31: =NA() -> #N/A | AO31: =NA() -> #N/A | AP31: =NA() -> #N/A
A32: 2.0638738e+08 | C32: -1291000 | D32: -6308000 | E32: 2103000 | F32: 4779 | G32: 903.1 | H32: 5549 | I32: 18.130365 | J32: -101.61292 | K32: 397093.56 | M32: 0.00025514513 | N32: -0.0075250864 | O32: -0.00075098127 | P32: 0.000628829 | Q32: 0.00022057444 | R32: -0.00015795231 | AJ32: =NA() -> #N/A | AK32: =NA() -> #N/A | AL32: =NA() -> #N/A | AM32: =NA() -> #N/A | AN32: =NA() -> #N/A | AO32: =NA() -> #N/A | AP32: =NA() -> #N/A
A33: 2.0638738e+08 | C33: -1289000 | D33: -6308000 | E33: 2104000 | F33: 4779 | G33: 904.9 | H33: 5549 | I33: 18.130365 | J33: -101.61292 | K33: 397093.56 | M33: -0.00059839338 | N33: 0.009021163 | O33: 0.00090602785 | P33: 0.00034272671 | Q33: 0.00027898699 | R33: -0.00011026859 | AJ33: =NA() -> #N/A | AK33: =NA() -> #N/A | AL33: =NA() -> #N/A | AM33: =NA() -> #N/A | AN33: =NA() -> #N/A | AO33: =NA() -> #N/A | AP33: =NA() -> #N/A
A34: 2.0638738e+08 | C34: -1288000 | D34: -6307000 | E34: 2105000 | F34: 4780 | G34: 906.7 | H34: 5548 | I34: 18.130365 | J34: -101.61292 | K34: 397093.56 | M34: 0.00024918467 | N34: -0.0073105097 | O34: -0.00073071569 | P34: 0.00053346157 | Q34: 0.00018958002 | R34: -0.00015795231 | AJ34: =NA() -> #N/A | AK34: =NA() -> #N/A | AL34: =NA() -> #N/A | AM34: =NA() -> #N/A | AN34: =NA() -> #N/A | AO34: =NA() -> #N/A | AP34: =NA() -> #N/A
A35: 2.0638738e+08 | C35: -1287000 | D35: -6307000 | E35: 2107000 | F35: 4780 | G35: 908.6 | H35: 5547 | I35: 18.130365 | J35: -101.61292 | K35: 397093.56 | M35: -0.00047560781 | N35: 0.0075429678 | O35: 0.00076297671 | P35: 0.00029504299 | Q35: 0.00024799258 | R35: -0.00011026859 | AJ35: =NA() -> #N/A | AK35: =NA() -> #N/A | AL35: =NA() -> #N/A | AM35: =NA() -> #N/A | AN35: =NA() -> #N/A | AO35: =NA() -> #N/A | AP35: =NA() -> #N/A
A36: 2.0638738e+08 | C36: -1286000 | D36: -6307000 | E36: 2108000 | F36: 4781 | G36: 910.4 | H36: 5546 | I36: 18.130365 | J36: -101.61292 | K36: 397093.56 | M36: 0.00026468188 | N36: -0.008764863 | O36: -0.00087615103 | P36: 0.00058114529 | Q36: 0.00020030886 | R36: -0.00018179417 | AJ36: =NA() -> #N/A | AK36: =NA() -> #N/A | AL36: =NA() -> #N/A | AM36: =NA() -> #N/A | AN36: =NA() -> #N/A | AO36: =NA() -> #N/A | AP36: =NA() -> #N/A
A37: 2.0638738e+08 | C37: -1285000 | D37: -6307000 | E37: 2109000 | F37: 4781 | G37: 912.3 | H37: 5546 | I37: 18.130365 | J37: -101.61292 | K37: 397093.56 | M37: -0.00049050897 | N37: 0.0077813864 | O37: 0.00078443438 | P37: 0.00034272671 | Q37: 0.00027302653 | R37: -0.00015795231 | AJ37: =NA() -> #N/A | AK37: =NA() -> #N/A | AL37: =NA() -> #N/A | AM37: =NA() -> #N/A | AN37: =NA() -> #N/A | AO37: =NA() -> #N/A | AP37: =NA() -> #N/A
A38: 2.0638738e+08 | C38: -1284000 | D38: -6307000 | E38: 2111000 | F38: 4782 | G38: 914.1 | H38: 5545 | I38: 18.130365 | J38: -101.61292 | K38: 397093.56 | M38: 0.00026468188 | N38: -0.0085502863 | O38: -0.00085469335 | P38: 0.000628829 | Q38: 0.00021819025 | R38: -0.00022947788 | AJ38: =NA() -> #N/A | AK38: =NA() -> #N/A | AL38: =NA() -> #N/A | AM38: =NA() -> #N/A | AN38: =NA() -> #N/A | AO38: =NA() -> #N/A | AP38: =NA() -> #N/A
A39: 2.0638738e+08 | C39: -1282000 | D39: -6306000 | E39: 2112000 | F39: 4782 | G39: 916 | H39: 5544 | I39: 18.130365 | J39: -101.61292 | K39: 397093.56 | M39: -0.0006538257 | N39: 0.0073522329 | O39: 0.00076297671 | P39: -0.0029474497 | Q39: -0.0012695417 | R39: -0.00011026859 | AJ39: =NA() -> #N/A | AK39: =NA() -> #N/A | AL39: =NA() -> #N/A | AM39: =NA() -> #N/A | AN39: =NA() -> #N/A | AO39: =NA() -> #N/A | AP39: =NA() -> #N/A
... A44: 2.0638738e+08 | C44: -1276000 | D44: -6305000 | E44: 2119000 | F44: 4784 | G44: 925.1 | H44: 5541 | I44: 18.130365 | J44: -101.61292 | K44: 397093.56 | M44: 0.00026825815 | N44: -0.0075250864 | O44: -0.0007539615 | P44: 0.00086724758 | Q44: 0.00033382326 | R44: -0.00015795231 | AJ44: =NA() -> #N/A | AK44: =NA() -> #N/A | AL44: =NA() -> #N/A | AM44: =NA() -> #N/A | AN44: =NA() -> #N/A | AO44: =NA() -> #N/A | AP44: =NA() -> #N/A
A45: 2.0638739e+08 | C45: -1275000 | D45: -6305000 | E45: 2120000 | F45: 4785 | G45: 927 | H45: 5540 | I45: 18.130365 | J45: -101.61292 | K45: 397093.56 | M45: -0.00072892755 | N45: 0.0084489584 | O45: 0.0008654967 | P45: -0.002732873 | Q45: -0.0011598691 | R45: -3.8743019e-05 | AJ45: =NA() -> #N/A | AK45: =NA() -> #N/A | AL45: =NA() -> #N/A | AM45: =NA() -> #N/A | AN45: =NA() -> #N/A | AO45: =NA() -> #N/A | AP45: 8
A46: 2.0638739e+08 | C46: -1259000 | D46: -6302000 | E46: 2140000 | F46: 4791 | G46: 952.8 | H46: 5531 | I46: 18.535755 | J46: -101.28586 | K46: 396945.28 | M46: 0.00018719584 | N46: -0.0082165003 | O46: -0.00081654638 | P46: -0.00082552433 | Q46: -0.00043686479 | R46: -6.2584877e-05 | AJ46: 1 | AK46: =NA() -> #N/A | AL46: =NA() -> #N/A | AM46: =NA() -> #N/A | AN46: =NA() -> #N/A | AO46: =NA() -> #N/A | AP46: =NA() -> #N/A
...

Sheet novatel_oem615_other
A1: CCSDS_STREAMID | B1: CCSDS_SEQUENCE | C1: CCSDS_LENGTH | D1: CCSDS_SECONDS | E1: CCSDS_SUBSECS | F1: CCSDS_SPARE | G1: GPS_WEEKS | H1: GPS_SECONDS | I1: GPS_FRAC_SECS | J1: ECEF_X | K1: ECEF_Y | L1: ECEF_Z | M1: VEL_X | N1: VEL_Y | O1: VEL_Z | P1: LAT | Q1: LON | R1: ALT
A2: 2161 | B2: 49333 | C2: 83 | D2: 61 | E2: 39976 | F2: 0 | G2: 341 | H2: 150279 | I2: 0.984 | J2: -2616000 | K2: -6243000 | L2: 354700 | M2: 4029 | N2: -1342 | O2: 6029 | P2: 2.6376984 | Q2: -113.00284 | R2: 400004.56
A3: 2161 | B3: 49334 | C3: 83 | D3: 61 | E3: 56360 | F3: 0 | G3: 341 | H3: 150280 | I3: 0.234 | J3: -2615000 | K3: -6243000 | L3: 356200 | M3: 4030 | N3: -1340 | O3: 6029 | P3: 2.6376984 | Q3: -113.00284 | R3: 400004.56
A4: 2161 | B4: 49335 | C4: 83 | D4: 62 | E4: 7208 | F4: 0 | G4: 341 | H4: 150280 | I4: 0.484 | J4: -2614000 | K4: -6243000 | L4: 357700 | M4: 4030 | N4: -1338 | O4: 6029 | P4: 2.6376984 | Q4: -113.00284 | R4: 400004.56
A5: 2161 | B5: 49336 | C5: 83 | D5: 62 | E5: 23592 | F5: 0 | G5: 341 | H5: 150280 | I5: 0.484 | J5: -2614000 | K5: -6243000 | L5: 357700 | M5: 4030 | N5: -1338 | O5: 6029 | P5: 3.0573797 | Q5: -112.71042 | R5: 399992.47
A6: 2161 | B6: 49337 | C6: 83 | D6: 62 | E6: 56360 | F6: 0 | G6: 341 | H6: 150281 | I6: 0.234 | J6: -2611000 | K6: -6244000 | L6: 362200 | M6: 4033 | N6: -1333 | O6: 6029 | P6: 3.0573797 | Q6: -112.71042 | R6: 399992.47
A7: 2161 | B7: 49338 | C7: 83 | D7: 63 | E7: 7208 | F7: 0 | G7: 341 | H7: 150281 | I7: 0.484 | J7: -2610000 | K7: -6245000 | L7: 363700 | M7: 4034 | N7: -1331 | O7: 6029 | P7: 3.0573797 | Q7: -112.71042 | R7: 399992.47
A8: 2161 | B8: 49339 | C8: 83 | D8: 63 | E8: 23592 | F8: 0 | G8: 341 | H8: 150281 | I8: 0.734 | J8: -2609000 | K8: -6245000 | L8: 365200 | M8: 4034 | N8: -1329 | O8: 6028 | P8: 3.0573797 | Q8: -112.71042 | R8: 399992.47
A9: 2161 | B9: 49340 | C9: 83 | D9: 63 | E9: 39976 | F9: 0 | G9: 341 | H9: 150281 | I9: 0.984 | J9: -2608000 | K9: -6245000 | L9: 366700 | M9: 4035 | N9: -1327 | O9: 6028 | P9: 3.0573797 | Q9: -112.71042 | R9: 399992.47
A10: 2161 | B10: 49341 | C10: 83 | D10: 63 | E10: 56360 | F10: 0 | G10: 341 | H10: 150282 | I10: 0.234 | J10: -2607000 | K10: -6246000 | L10: 368200 | M10: 4036 | N10: -1325 | O10: 6028 | P10: 3.0573797 | Q10: -112.71042 | R10: 399992.47
A11: 2161 | B11: 49342 | C11: 83 | D11: 64 | E11: 7208 | F11: 0 | G11: 341 | H11: 150282 | I11: 0.484 | J11: -2606000 | K11: -6246000 | L11: 369700 | M11: 4037 | N11: -1323 | O11: 6028 | P11: 3.0573797 | Q11: -112.71042 | R11: 399992.47
A12: 2161 | B12: 49343 | C12: 83 | D12: 64 | E12: 23592 | F12: 0 | G12: 341 | H12: 150282 | I12: 0.734 | J12: -2605000 | K12: -6246000 | L12: 371200 | M12: 4037 | N12: -1322 | O12: 6028 | P12: 3.0573797 | Q12: -112.71042 | R12: 399992.47
A13: 2161 | B13: 49344 | C13: 83 | D13: 64 | E13: 39976 | F13: 0 | G13: 341 | H13: 150282 | I13: 0.984 | J13: -2604000 | K13: -6247000 | L13: 372600 | M13: 4038 | N13: -1320 | O13: 6028 | P13: 3.0573797 | Q13: -112.71042 | R13: 399992.47
... A499: 2161 | B499: 49852 | C499: 83 | D499: 197 | E499: 19660 | F499: 0 | G499: 341 | H499: 150415 | I499: 0.734 | J499: -2048000 | K499: -6355000 | L499: 1158000 | M499: 4417 | N499: -332.9 | O499: 5898 | P499: 9.6835527 | Q499: -108.02025 | R499: 399322
A500: 2161 | B500: 49853 | C500: 83 | D500: 197 | E500: 36700 | F500: 0 | G500: =NA() -> #N/A | H500: =NA() -> #N/A | I500: =NA() -> #N/A | J500: =NA() -> #N/A | K500: =NA() -> #N/A | L500: =NA() -> #N/A | M500: =NA() -> #N/A | N500: =NA() -> #N/A | ... R500: =NA() -> #N/A
A501: 2161 | B501: 49854 | C501: 83 | D501: 197 | E501: 53084 | F501: 0 | G501: =NA() -> #N/A | H501: =NA() -> #N/A | I501: =NA() -> #N/A | J501: =NA() -> #N/A | K501: =NA() -> #N/A | L501: =NA() -> #N/A | M501: =NA() -> #N/A | N501: =NA() -> #N/A | ... R501: =NA() -> #N/A
A502: 2161 | B502: 49855 | C502: 83 | D502: 198 | E502: 3932 | F502: 0 | G502: =NA() -> #N/A | H502: =NA() -> #N/A | I502: =NA() -> #N/A | J502: =NA() -> #N/A | K502: =NA() -> #N/A | L502: =NA() -> #N/A | M502: =NA() -> #N/A | N502: =NA() -> #N/A | ... R502: =NA() -> #N/A
A503: 2161 | B503: 49856 | C503: 83 | D503: 198 | E503: 20316 | F503: 0 | G503: =NA() -> #N/A | H503: =NA() -> #N/A | I503: =NA() -> #N/A | J503: =NA() -> #N/A | K503: =NA() -> #N/A | L503: =NA() -> #N/A | M503: =NA() -> #N/A | N503: =NA() -> #N/A | ... R503: =NA() -> #N/A
A504: 2161 | B504: 49857 | C504: 83 | D504: 198 | E504: 36700 | F504: 0 | G504: =NA() -> #N/A | H504: =NA() -> #N/A | I504: =NA() -> #N/A | J504: =NA() -> #N/A | K504: =NA() -> #N/A | L504: =NA() -> #N/A | M504: =NA() -> #N/A | N504: =NA() -> #N/A | ... R504: =NA() -> #N/A
A505: 2161 | B505: 49858 | C505: 83 | D505: 198 | E505: 53084 | F505: 0 | G505: =NA() -> #N/A | H505: =NA() -> #N/A | I505: =NA() -> #N/A | J505: =NA() -> #N/A | K505: =NA() -> #N/A | L505: =NA() -> #N/A | M505: =NA() -> #N/A | N505: =NA() -> #N/A | ... R505: =NA() -> #N/A
A506: 2161 | B506: 49859 | C506: 83 | D506: 199 | E506: 3932 | F506: 0 | G506: =NA() -> #N/A | H506: =NA() -> #N/A | I506: =NA() -> #N/A | J506: =NA() -> #N/A | K506: =NA() -> #N/A | L506: =NA() -> #N/A | M506: =NA() -> #N/A | N506: =NA() -> #N/A | ... R506: =NA() -> #N/A
A507: 2161 | B507: 49860 | C507: 83 | D507: 199 | E507: 20316 | F507: 0 | G507: =NA() -> #N/A | H507: =NA() -> #N/A | I507: =NA() -> #N/A | J507: =NA() -> #N/A | K507: =NA() -> #N/A | L507: =NA() -> #N/A | M507: =NA() -> #N/A | N507: =NA() -> #N/A | ... R507: =NA() -> #N/A
A508: 2161 | B508: 49861 | C508: 83 | D508: 199 | E508: 36700 | F508: 0 | G508: =NA() -> #N/A | H508: =NA() -> #N/A | I508: =NA() -> #N/A | J508: =NA() -> #N/A | K508: =NA() -> #N/A | L508: =NA() -> #N/A | M508: =NA() -> #N/A | N508: =NA() -> #N/A | ... R508: =NA() -> #N/A
A509: 2161 | B509: 49862 | C509: 83 | D509: 199 | E509: 53084 | F509: 0 | G509: =NA() -> #N/A | H509: =NA() -> #N/A | I509: =NA() -> #N/A | J509: =NA() -> #N/A | K509: =NA() -> #N/A | L509: =NA() -> #N/A | M509: =NA() -> #N/A | N509: =NA() -> #N/A | ... R509: =NA() -> #N/A
A510: 2161 | B510: 49863 | C510: 83 | D510: 200 | E510: 3932 | F510: 0 | G510: =NA() -> #N/A | H510: =NA() -> #N/A | I510: =NA() -> #N/A | J510: =NA() -> #N/A | K510: =NA() -> #N/A | L510: =NA() -> #N/A | M510: =NA() -> #N/A | N510: =NA() -> #N/A | ... R510: =NA() -> #N/A
A511: 2161 | B511: 49864 | C511: 83 | D511: 200 | E511: 20316 | F511: 0 | G511: =NA() -> #N/A | H511: =NA() -> #N/A | I511: =NA() -> #N/A | J511: =NA() -> #N/A | K511: =NA() -> #N/A | L511: =NA() -> #N/A | M511: =NA() -> #N/A | N511: =NA() -> #N/A | ... R511: =NA() -> #N/A
... A600: 2161 | B600: 49953 | C600: 83 | D600: 223 | E600: 57016 | F600: 0 | G600: =NA() -> #N/A | H600: =NA() -> #N/A | I600: =NA() -> #N/A | J600: =NA() -> #N/A | K600: =NA() -> #N/A | L600: =NA() -> #N/A | M600: =NA() -> #N/A | N600: =NA() -> #N/A | ... R600: =NA() -> #N/A
A601: 2161 | B601: 49954 | C601: 83 | D601: 224 | E601: 7864 | F601: 0 | G601: 341 | H601: 150442 | I601: 0.484 | J601: -1931000 | K601: -6361000 | L601: 1313000 | M601: 4484 | N601: -133.2 | O601: 5855 | P601: 11.194542 | Q601: -106.91989 | R601: 399049.78
A602: 2161 | B602: 49955 | C602: 83 | D602: 224 | E602: 24248 | F602: 0 | G602: 341 | H602: 150442 | I602: 0.734 | J602: -1930000 | K602: -6361000 | L602: 1315000 | M602: 4484 | N602: -131.4 | O602: 5855 | P602: 11.194542 | Q602: -106.91989 | R602: 399049.78
A603: 2161 | B603: 49956 | C603: 83 | D603: 224 | E603: 40632 | F603: 0 | G603: 341 | H603: 150442 | I603: 0.984 | J603: -1928000 | K603: -6361000 | L603: 1316000 | M603: 4485 | N603: -129.5 | O603: 5854 | P603: 11.194542 | Q603: -106.91989 | R603: 399049.78
A604: 2161 | B604: 49957 | C604: 83 | D604: 224 | E604: 57016 | F604: 0 | G604: 341 | H604: 150443 | I604: 0.234 | J604: -1927000 | K604: -6361000 | L604: 1318000 | M604: 4486 | N604: -127.6 | O604: 5854 | P604: 11.194542 | Q604: -106.91989 | R604: 399049.78
A605: 2161 | B605: 49958 | C605: 83 | D605: 225 | E605: 7864 | F605: 0 | G605: 341 | H605: 150443 | I605: 0.484 | J605: -1926000 | K605: -6361000 | L605: 1319000 | M605: 4486 | N605: -125.8 | O605: 5854 | P605: 11.194542 | Q605: -106.91989 | R605: 399049.78
A606: 2161 | B606: 49959 | C606: 83 | D606: 225 | E606: 24248 | F606: 0 | G606: 341 | H606: 150443 | I606: 0.734 | J606: -1925000 | K606: -6362000 | L606: 1321000 | M606: 4487 | N606: -123.9 | O606: 5853 | P606: 11.194542 | Q606: -106.91989 | R606: 399049.78
A607: 2161 | B607: 49960 | C607: 83 | D607: 225 | E607: 40632 | F607: 0 | G607: 341 | H607: 150443 | I607: 0.984 | J607: -1924000 | K607: -6362000 | L607: 1322000 | M607: 4487 | N607: -122 | O607: 5853 | P607: 11.194542 | Q607: -106.91989 | R607: 399049.78
A608: 2161 | B608: 49961 | C608: 83 | D608: 225 | E608: 57016 | F608: 0 | G608: 341 | H608: 150444 | I608: 0.234 | J608: -1923000 | K608: -6362000 | L608: 1324000 | M608: 4488 | N608: -120.2 | O608: 5852 | P608: 11.194542 | Q608: -106.91989 | R608: 399049.78
A609: 2161 | B609: 49962 | C609: 83 | D609: 226 | E609: 7864 | F609: 0 | G609: 341 | H609: 150444 | I609: 0.484 | J609: -1922000 | K609: -6362000 | L609: 1325000 | M609: 4489 | N609: -118.3 | O609: 5852 | P609: 11.194542 | Q609: -106.91989 | R609: 399049.78
A610: 2161 | B610: 49963 | C610: 83 | D610: 226 | E610: 24248 | F610: 0 | G610: 341 | H610: 150444 | I610: 0.734 | J610: -1921000 | K610: -6362000 | L610: 1326000 | M610: 4489 | N610: -116.4 | O610: 5851 | P610: 11.194542 | Q610: -106.91989 | R610: 399049.78
A611: 2161 | B611: 49964 | C611: 83 | D611: 226 | E611: 40632 | F611: 0 | G611: 341 | H611: 150444 | I611: 0.984 | J611: -1920000 | K611: -6362000 | L611: 1328000 | M611: 4490 | N611: -114.5 | O611: 5851 | P611: 11.194542 | Q611: -106.91989 | R611: 399049.78
A612: 2161 | B612: 49965 | C612: 83 | D612: 226 | E612: 57671 | F612: 0 | G612: 341 | H612: 150445 | I612: 0.234 | J612: -1918000 | K612: -6362000 | L612: 1329000 | M612: 4490 | N612: -112.7 | O612: 5851 | P612: 11.194542 | Q612: -106.91989 | R612: 399049.78
... A849: 2161 | B849: 50202 | C849: 83 | D849: 288 | E849: 63569 | F849: 0 | G849: 341 | H849: 150507 | I849: 0.484 | J849: -1638000 | K849: -6354000 | L849: 1686000 | M849: 4633 | N849: 351.3 | O849: 5730 | P849: 14.400352 | Q849: -104.52711 | R849: 398281.03

Sheet generic_imu_other
A1: CCSDS_STREAMID | B1: CCSDS_SEQUENCE | C1: CCSDS_LENGTH | D1: CCSDS_SECONDS | E1: CCSDS_SUBSECS | F1: CCSDS_SPARE | G1: X_LINEAR_ACCELERATION | H1: X_ANGULAR_RATE | I1: Y_LINEAR_ACCELERATION | J1: Y_ANGULAR_RATE | K1: Z_LINEAR_ACCELERATION | L1: Z_ANGULAR_RATE
A2: 2342 | B2: 49203 | C2: 33 | D2: 62 | E2: 1310 | F2: 0 | G2: -0.0014966354 | H2: 0.0043004751 | I2: 0.0014317408 | J2: 0.003489852 | K2: -0.0039344653 | L2: -0.030532479
A3: 2342 | B3: 49204 | C3: 33 | D3: 63 | E3: 1310 | F3: 0 | G3: -0.0013470277 | H3: -0.0059992075 | I3: -0.00011082739 | J3: 0.0038713217 | K3: -0.0031888112 | L3: -0.029245019
A4: 2342 | B4: 49205 | C4: 33 | D4: 64 | E4: 1310 | F4: 0 | G4: -0.0013666973 | H4: 0.0039190054 | I4: 0.0014186278 | J4: 0.0029653311 | K4: -0.0033157691 | L4: -0.028386712
A5: 2342 | B5: 49206 | C5: 33 | D5: 65 | E5: 1310 | F5: 0 | G5: -0.0012701377 | H5: -0.0061184168 | I5: -7.8640878e-05 | J5: 0.0037282705 | K5: -0.0026529655 | L5: -0.028434396
A6: 2342 | B6: 49207 | C6: 33 | D6: 66 | E6: 1310 | F6: 0 | G6: -0.0013297424 | H6: 0.0059217215 | I6: 0.001716651 | J6: 0.0037759542 | K6: -0.0022941455 | L6: -0.027266145
A7: 2342 | B7: 49208 | C7: 33 | D7: 67 | E7: 1310 | F7: 0 | G7: -0.0011467561 | H7: -0.0073105097 | I7: -0.00020142645 | J7: 0.0032514334 | K7: -0.0021105632 | L7: -0.026288629
A8: 2342 | B8: 49209 | C8: 33 | D8: 68 | E8: 1310 | F8: 0 | G8: -0.0013196096 | H8: 0.0063508749 | I8: 0.0018227473 | J8: 0.0023454428 | K8: -0.0024294481 | L8: -0.02643168
A9: 2342 | B9: 49210 | C9: 33 | D9: 69 | E9: 1310 | F9: 0 | G9: -0.0010889396 | H9: -0.0091224909 | I9: -0.00043209642 | J9: 0.0032514334 | K9: -0.0015675649 | L9: -0.025120378
A10: 2342 | B10: 49211 | C10: 33 | D10: 70 | E10: 1310 | F10: 0 | G10: -0.0011866912 | H10: 0.0066369772 | I10: 0.0018179789 | J10: 0.0033468008 | K10: -0.0013106689 | L10: -0.024262071
A11: 2342 | B11: 49212 | C11: 33 | D11: 71 | E11: 1310 | F11: 0 | G11: -0.00098463148 | H11: -0.0076681376 | I11: -0.00020321459 | J11: 0.0029176474 | K11: -0.001286231 | L11: -0.024309754
A12: 2342 | B12: 49213 | C12: 33 | D12: 72 | E12: 1310 | F12: 0 | G12: -0.0012266263 | H12: 0.0080674887 | I12: 0.0020301715 | J12: 0.0020116568 | K12: -0.0014692172 | L12: -0.02309382
A13: 2342 | B13: 49214 | C13: 33 | D13: 73 | E13: 1310 | F13: 0 | G13: -0.00085648149 | H13: -0.0087887049 | I13: -0.00034388155 | J13: 0.0029653311 | K13: -0.00071879476 | L13: -0.022116303
... A227: 2342 | B227: 49429 | C227: 33 | D227: 288 | E227: 1310 | F227: 0 | G227: -0.00056322664 | H227: 0.0084966421 | I227: 0.00081662089 | J227: 5.6624413e-05 | K227: 9.778887e-05 | L227: 0.00039041042

Sheet All errors
A1: Novatel timestamp | C1: ECEF_X | D1: ECEF_Y | E1: ECEF_Z | F1: VEL_X | G1: VEL_Y | H1: VEL_Z | I1: LAT | J1: LON | K1: ALT | M1: X_LINEAR_ACCELERATION | N1: X_ANGULAR_RATE | O1: Y_LINEAR_ACCELERATION | P1: Y_ANGULAR_RATE | Q1: Z_LINEAR_ACCELERATION | R1: Z_ANGULAR_RATE | AJ1: time_jump | AK1: pos_jump | AL1: velocity_mismatch | AM1: imu_mismatch | AN1: stale_gnss | AO1: heading_mismatch | AP1: frozen_position
A2: {=novatel_oem615_other!G2:G849*604800+novatel_oem615_other!H2:H849+novatel_oem615_other!I2:I849} -> 2.0638708e+08 | C2: {=novatel_oem615_other!J2:J849} -> -2616000 | D2: {=novatel_oem615_other!K2:K849} -> -6243000 | E2: {=novatel_oem615_other!L2:L849} -> 354700 | F2: {=novatel_oem615_other!M2:M849} -> 4029 | G2: {=novatel_oem615_other!N2:N849} -> -1342 | H2: {=novatel_oem615_other!O2:O849} -> 6029 | I2: {=novatel_oem615_other!P2:P849} -> 2.6376984 | J2: {=novatel_oem615_other!Q2:Q849} -> -113.00284 | K2: {=novatel_oem615_other!R2:R849} -> 400004.56 | M2: {=generic_imu_other!G2:G227} -> -0.0014966354 | N2: {=generic_imu_other!H2:H227} -> 0.0043004751 | O2: {=generic_imu_other!I2:I227} -> 0.0014317408 | P2: {=generic_imu_other!J2:J227} -> 0.003489852 | Q2: {=generic_imu_other!K2:K227} -> -0.0039344653 | R2: {=generic_imu_other!L2:L227} -> -0.030532479 | AJ2: 1 | AK2: =NA() -> #N/A | AL2: 3 | AM2: =NA() -> #N/A | AN2: 5 | AO2: =NA() -> #N/A | AP2: =NA() -> #N/A
A3: 2.0638708e+08 | C3: -2615000 | D3: -6243000 | E3: 356200 | F3: 4030 | G3: -1340 | H3: 6029 | I3: 2.6376984 | J3: -113.00284 | K3: 400004.56 | M3: -0.0013470277 | N3: -0.0059992075 | O3: -0.00011082739 | P3: 0.0038713217 | Q3: -0.0031888112 | R3: -0.029245019 | AJ3: =NA() -> #N/A | AK3: =NA() -> #N/A | AL3: =NA() -> #N/A | AM3: =NA() -> #N/A | AN3: =NA() -> #N/A | AO3: =NA() -> #N/A | AP3: =NA() -> #N/A
A4: 2.0638708e+08 | C4: -2614000 | D4: -6243000 | E4: 357700 | F4: 4030 | G4: -1338 | H4: 6029 | I4: 2.6376984 | J4: -113.00284 | K4: 400004.56 | M4: -0.0013666973 | N4: 0.0039190054 | O4: 0.0014186278 | P4: 0.0029653311 | Q4: -0.0033157691 | R4: -0.028386712 | AJ4: =NA() -> #N/A | AK4: =NA() -> #N/A | AL4: =NA() -> #N/A | AM4: =NA() -> #N/A | AN4: =NA() -> #N/A | AO4: =NA() -> #N/A | AP4: =NA() -> #N/A
A5: 2.0638708e+08 | C5: -2614000 | D5: -6243000 | E5: 357700 | F5: 4030 | G5: -1338 | H5: 6029 | I5: 3.0573797 | J5: -112.71042 | K5: 399992.47 | M5: -0.0012701377 | N5: -0.0061184168 | O5: -7.8640878e-05 | P5: 0.0037282705 | Q5: -0.0026529655 | R5: -0.028434396 | AJ5: 1 | AK5: =NA() -> #N/A | AL5: 3 | AM5: =NA() -> #N/A | AN5: =NA() -> #N/A | AO5: =NA() -> #N/A | AP5: =NA() -> #N/A
A6: 2.0638708e+08 | C6: -2611000 | D6: -6244000 | E6: 362200 | F6: 4033 | G6: -1333 | H6: 6029 | I6: 3.0573797 | J6: -112.71042 | K6: 399992.47 | M6: -0.0013297424 | N6: 0.0059217215 | O6: 0.001716651 | P6: 0.0037759542 | Q6: -0.0022941455 | R6: -0.027266145 | AJ6: =NA() -> #N/A | AK6: =NA() -> #N/A | AL6: =NA() -> #N/A | AM6: =NA() -> #N/A | AN6: =NA() -> #N/A | AO6: =NA() -> #N/A | AP6: =NA() -> #N/A
A7: 2.0638708e+08 | C7: -2610000 | D7: -6245000 | E7: 363700 | F7: 4034 | G7: -1331 | H7: 6029 | I7: 3.0573797 | J7: -112.71042 | K7: 399992.47 | M7: -0.0011467561 | N7: -0.0073105097 | O7: -0.00020142645 | P7: 0.0032514334 | Q7: -0.0021105632 | R7: -0.026288629 | AJ7: =NA() -> #N/A | AK7: =NA() -> #N/A | AL7: =NA() -> #N/A | AM7: =NA() -> #N/A | AN7: =NA() -> #N/A | AO7: =NA() -> #N/A | AP7: =NA() -> #N/A
A8: 2.0638708e+08 | C8: -2609000 | D8: -6245000 | E8: 365200 | F8: 4034 | G8: -1329 | H8: 6028 | I8: 3.0573797 | J8: -112.71042 | K8: 399992.47 | M8: -0.0013196096 | N8: 0.0063508749 | O8: 0.0018227473 | P8: 0.0023454428 | Q8: -0.0024294481 | R8: -0.02643168 | AJ8: =NA() -> #N/A | AK8: =NA() -> #N/A | AL8: =NA() -> #N/A | AM8: =NA() -> #N/A | AN8: =NA() -> #N/A | AO8: =NA() -> #N/A | AP8: =NA() -> #N/A
A9: 2.0638708e+08 | C9: -2608000 | D9: -6245000 | E9: 366700 | F9: 4035 | G9: -1327 | H9: 6028 | I9: 3.0573797 | J9: -112.71042 | K9: 399992.47 | M9: -0.0010889396 | N9: -0.0091224909 | O9: -0.00043209642 | P9: 0.0032514334 | Q9: -0.0015675649 | R9: -0.025120378 | AJ9: =NA() -> #N/A | AK9: =NA() -> #N/A | AL9: =NA() -> #N/A | AM9: =NA() -> #N/A | AN9: =NA() -> #N/A | AO9: =NA() -> #N/A | AP9: =NA() -> #N/A
A10: 2.0638708e+08 | C10: -2607000 | D10: -6246000 | E10: 368200 | F10: 4036 | G10: -1325 | H10: 6028 | I10: 3.0573797 | J10: -112.71042 | K10: 399992.47 | M10: -0.0011866912 | N10: 0.0066369772 | O10: 0.0018179789 | P10: 0.0033468008 | Q10: -0.0013106689 | R10: -0.024262071 | AJ10: =NA() -> #N/A | AK10: =NA() -> #N/A | AL10: =NA() -> #N/A | AM10: =NA() -> #N/A | AN10: =NA() -> #N/A | AO10: =NA() -> #N/A | AP10: =NA() -> #N/A
A11: 2.0638708e+08 | C11: -2606000 | D11: -6246000 | E11: 369700 | F11: 4037 | G11: -1323 | H11: 6028 | I11: 3.0573797 | J11: -112.71042 | K11: 399992.47 | M11: -0.00098463148 | N11: -0.0076681376 | O11: -0.00020321459 | P11: 0.0029176474 | Q11: -0.001286231 | R11: -0.024309754 | AJ11: =NA() -> #N/A | AK11: =NA() -> #N/A | AL11: =NA() -> #N/A | AM11: =NA() -> #N/A | AN11: =NA() -> #N/A | AO11: =NA() -> #N/A | AP11: =NA() -> #N/A
A12: 2.0638708e+08 | C12: -2605000 | D12: -6246000 | E12: 371200 | F12: 4037 | G12: -1322 | H12: 6028 | I12: 3.0573797 | J12: -112.71042 | K12: 399992.47 | M12: -0.0012266263 | N12: 0.0080674887 | O12: 0.0020301715 | P12: 0.0020116568 | Q12: -0.0014692172 | R12: -0.02309382 | AJ12: =NA() -> #N/A | AK12: =NA() -> #N/A | AL12: =NA() -> #N/A | AM12: =NA() -> #N/A | AN12: =NA() -> #N/A | AO12: =NA() -> #N/A | AP12: =NA() -> #N/A
A13: 2.0638708e+08 | C13: -2604000 | D13: -6247000 | E13: 372600 | F13: 4038 | G13: -1320 | H13: 6028 | I13: 3.0573797 | J13: -112.71042 | K13: 399992.47 | M13: -0.00085648149 | N13: -0.0087887049 | O13: -0.00034388155 | P13: 0.0029653311 | Q13: -0.00071879476 | R13: -0.022116303 | AJ13: =NA() -> #N/A | AK13: =NA() -> #N/A | AL13: =NA() -> #N/A | AM13: =NA() -> #N/A | AN13: =NA() -> #N/A | AO13: =NA() -> #N/A | AP13: =NA() -> #N/A
A14: 2.0638708e+08 | C14: -2603000 | D14: -6247000 | E14: 374100 | F14: 4039 | G14: -1318 | H14: 6028 | I14: 3.0573797 | J14: -112.71042 | K14: 399992.47 | M14: -0.0010704622 | N14: 0.0073522329 | O14: 0.0018728152 | P14: 0.0031560659 | Q14: -0.00048633665 | R14: -0.021591783 | AJ14: =NA() -> #N/A | AK14: =NA() -> #N/A | AL14: =NA() -> #N/A | AM14: =NA() -> #N/A | AN14: =NA() -> #N/A | AO14: =NA() -> #N/A | AP14: =NA() -> #N/A
A15: 2.0638708e+08 | C15: -2602000 | D15: -6247000 | E15: 375600 | F15: 4040 | G15: -1316 | H15: 6028 | I15: 3.0573797 | J15: -112.71042 | K15: 399992.47 | M15: -0.0007384643 | N15: -0.0080019236 | O15: -0.000234209 | P15: 0.0027745962 | Q15: -0.00041063875 | R15: -0.020638108 | AJ15: =NA() -> #N/A | AK15: =NA() -> #N/A | AL15: =NA() -> #N/A | AM15: =NA() -> #N/A | AN15: =NA() -> #N/A | AO15: =NA() -> #N/A | AP15: =NA() -> #N/A
A16: 2.0638708e+08 | C16: -2601000 | D16: -6248000 | E16: 377100 | F16: 4041 | G16: -1314 | H16: 6028 | I16: 3.0573797 | J16: -112.71042 | K16: 399992.47 | M16: -0.0010734424 | N16: 0.0081151724 | O16: 0.0019491091 | P16: 0.001963973 | Q16: -0.00064250082 | R16: -0.020089746 | AJ16: =NA() -> #N/A | AK16: =NA() -> #N/A | AL16: =NA() -> #N/A | AM16: =NA() -> #N/A | AN16: =NA() -> #N/A | AO16: =NA() -> #N/A | AP16: =NA() -> #N/A
A17: 2.0638708e+08 | C17: -2600000 | D17: -6248000 | E17: 378600 | F17: 4041 | G17: -1312 | H17: 6027 | I17: 3.0573797 | J17: -112.71042 | K17: 399992.47 | M17: -0.00068482012 | N17: -0.0084072351 | O17: -0.00029500574 | P17: 0.0029653311 | Q17: -2.9169023e-05 | R17: -0.020113587 | AJ17: =NA() -> #N/A | AK17: =NA() -> #N/A | AL17: =NA() -> #N/A | AM17: =NA() -> #N/A | AN17: =NA() -> #N/A | AO17: =NA() -> #N/A | AP17: =NA() -> #N/A
... A21: 2.0638708e+08 | C21: -2596000 | D21: -6249000 | E21: 384600 | F21: 4044 | G21: -1305 | H21: 6027 | I21: 3.0573797 | J21: -112.71042 | K21: 399992.47 | M21: -0.00049289316 | N21: -0.0079780817 | O21: -0.00026281923 | P21: 0.0024884939 | Q21: 0.00034932047 | R21: -0.017157197 | AJ21: =NA() -> #N/A | AK21: =NA() -> #N/A | AL21: =NA() -> #N/A | AM21: =NA() -> #N/A | AN21: =NA() -> #N/A | AO21: =NA() -> #N/A | AP21: =NA() -> #N/A
A22: 2.0638708e+08 | C22: -2596000 | D22: -6249000 | E22: 384600 | F22: 4044 | G22: -1305 | H22: 6027 | I22: 3.285898 | J22: -112.55113 | K22: 399983 | M22: -0.0009220466 | N22: 0.008687377 | O22: 0.001896657 | P22: 0.0027745962 | Q22: 0.00059369951 | R22: -0.017276406 | AJ22: 1 | AK22: =NA() -> #N/A | AL22: 3 | AM22: =NA() -> #N/A | AN22: =NA() -> #N/A | AO22: =NA() -> #N/A | AP22: =NA() -> #N/A
A23: 2.0638709e+08 | C23: -2593000 | D23: -6250000 | E23: 389100 | F23: 4047 | G23: -1299 | H23: 6027 | I23: 3.285898 | J23: -112.55113 | K23: 399983 | M23: -0.00044938177 | N23: -0.0074535608 | O23: -0.00021096319 | P23: 0.0031560659 | Q23: 0.00082973391 | R23: -0.017347932 | AJ23: =NA() -> #N/A | AK23: =NA() -> #N/A | AL23: =NA() -> #N/A | AM23: =NA() -> #N/A | AN23: =NA() -> #N/A | AO23: =NA() -> #N/A | AP23: =NA() -> #N/A
A24: 2.0638709e+08 | C24: -2592000 | D24: -6251000 | E24: 390500 | F24: 4048 | G24: -1298 | H24: 6026 | I24: 3.285898 | J24: -112.55113 | K24: 399983 | M24: -0.00081118196 | N24: 0.0076383352 | O24: 0.0017118827 | P24: 0.0024884939 | Q24: 0.00067714602 | R24: -0.016108155 | AJ24: =NA() -> #N/A | AK24: =NA() -> #N/A | AL24: =NA() -> #N/A | AM24: =NA() -> #N/A | AN24: =NA() -> #N/A | AO24: =NA() -> #N/A | AP24: =NA() -> #N/A
A25: 2.0638709e+08 | C25: -2591000 | D25: -6251000 | E25: 392000 | F25: 4048 | G25: -1296 | H25: 6026 | I25: 3.285898 | J25: -112.55113 | K25: 399983 | M25: -0.00036831945 | N25: -0.0085502863 | O25: -0.00037368387 | P25: 0.0022977591 | Q25: 0.00064972788 | R25: -0.015154481 | AJ25: =NA() -> #N/A | AK25: =NA() -> #N/A | AL25: =NA() -> #N/A | AM25: =NA() -> #N/A | AN25: =NA() -> #N/A | AO25: =NA() -> #N/A | AP25: =NA() -> #N/A
A26: 2.0638709e+08 | C26: -2590000 | D26: -6251000 | E26: 393500 | F26: 4049 | G26: -1294 | H26: 6026 | I26: 3.285898 | J26: -112.55113 | K26: 399983 | M26: -0.0008052215 | N26: 0.0082582235 | O26: 0.0017476454 | P26: 0.0026315451 | Q26: 0.00092986971 | R26: -0.015249848 | AJ26: =NA() -> #N/A | AK26: =NA() -> #N/A | AL26: =NA() -> #N/A | AM26: =NA() -> #N/A | AN26: =NA() -> #N/A | AO26: =NA() -> #N/A | AP26: =NA() -> #N/A
A27: 2.0638709e+08 | C27: -2589000 | D27: -6252000 | E27: 395100 | F27: 4050 | G27: -1292 | H27: 6026 | I27: 3.285898 | J27: -112.55113 | K27: 399983 | M27: -0.00032003969 | N27: -0.0077158213 | O27: -0.00028666109 | P27: 0.0031083822 | Q27: 0.0011551753 | R27: -0.015321374 | AJ27: =NA() -> #N/A | AK27: =NA() -> #N/A | AL27: =NA() -> #N/A | AM27: =NA() -> #N/A | AN27: =NA() -> #N/A | AO27: =NA() -> #N/A | AP27: =NA() -> #N/A
A28: 2.0638709e+08 | C28: -2584000 | D28: -6252000 | E28: 396500 | F28: 4051 | G28: -1290 | H28: 6026 | I28: 3.285898 | J28: -112.55113 | K28: 399983 | M28: -0.00082012266 | N28: 0.0092118979 | O28: 0.0018036738 | P28: 0.0027745962 | Q28: 0.0011623278 | R28: -0.014081597 | AJ28: =NA() -> #N/A | AK28: 2 | AL28: 3 | AM28: =NA() -> #N/A | AN28: =NA() -> #N/A | AO28: =NA() -> #N/A | AP28: =NA() -> #N/A
A29: 2.0638709e+08 | C29: -2579000 | D29: -6252000 | E29: 398000 | F29: 4051 | G29: -1288 | H29: 6026 | I29: 3.285898 | J29: -112.55113 | K29: 399983 | M29: -0.00019963831 | N29: -0.0066429377 | O29: -0.00020261854 | P29: 0.0032514334 | Q29: 0.0013637915 | R29: -0.013175607 | AJ29: =NA() -> #N/A | AK29: 2 | AL29: 3 | AM29: =NA() -> #N/A | AN29: =NA() -> #N/A | AO29: =NA() -> #N/A | AP29: =NA() -> #N/A
A30: 2.0638709e+08 | C30: -2574000 | D30: -6252000 | E30: 399500 | F30: 4052 | G30: -1286 | H30: 6026 | I30: 3.285898 | J30: -112.55113 | K30: 399983 | M30: -0.00063296407 | N30: 0.0071138144 | O30: 0.0014913455 | P30: 0.0030130148 | Q30: 0.0013900176 | R30: -0.013270974 | AJ30: =NA() -> #N/A | AK30: 2 | AL30: 3 | AM30: =NA() -> #N/A | AN30: =NA() -> #N/A | AO30: =NA() -> #N/A | AP30: =NA() -> #N/A
A31: 2.0638709e+08 | C31: -2569000 | D31: -6253000 | E31: 401000 | F31: 4053 | G31: -1285 | H31: 6026 | I31: 3.285898 | J31: -112.55113 | K31: 399983 | M31: -0.00020321459 | N31: -0.0072866678 | O31: -0.00028606504 | P31: 0.0028699636 | Q31: 0.0013006106 | R31: -0.0133425 | AJ31: =NA() -> #N/A | AK31: 2 | AL31: 3 | AM31: =NA() -> #N/A | AN31: =NA() -> #N/A | AO31: =NA() -> #N/A | AP31: =NA() -> #N/A
A32: 2.0638709e+08 | C32: -2564000 | D32: -6253000 | E32: 402500 | F32: 4054 | G32: -1283 | H32: 6025 | I32: 3.285898 | J32: -112.55113 | K32: 399983 | M32: -0.00067707151 | N32: 0.008019805 | O32: 0.0015485659 | P32: 0.0022977591 | Q32: 0.0011623278 | R32: -0.012078881 | AJ32: =NA() -> #N/A | AK32: 2 | AL32: 3 | AM32: =NA() -> #N/A | AN32: =NA() -> #N/A | AO32: =NA() -> #N/A | AP32: =NA() -> #N/A
A33: 2.0638709e+08 | C33: -2559000 | D33: -6253000 | E33: 404000 | F33: 4055 | G33: -1281 | H33: 6025 | I33: 3.285898 | J33: -112.55113 | K33: 399983 | M33: -0.00010188669 | N33: -0.0078350306 | O33: -0.00040408224 | P33: 0.0028699636 | Q33: 0.0013733283 | R33: -0.011172891 | AJ33: =NA() -> #N/A | AK33: 2 | AL33: 3 | AM33: =NA() -> #N/A | AN33: =NA() -> #N/A | AO33: =NA() -> #N/A | AP33: =NA() -> #N/A
A34: 2.0638709e+08 | C34: -2554000 | D34: -6254000 | E34: 405500 | F34: 4055 | G34: -1279 | H34: 6025 | I34: 3.285898 | J34: -112.55113 | K34: 399983 | M34: -0.00070687383 | N34: 0.0092118979 | O34: 0.0015962496 | P34: 0.0026315451 | Q34: 0.0014114752 | R34: -0.010576844 | AJ34: =NA() -> #N/A | AK34: 2 | AL34: 3 | AM34: =NA() -> #N/A | AN34: =NA() -> #N/A | AO34: =NA() -> #N/A | AP34: =NA() -> #N/A
A35: 2.0638709e+08 | C35: -2549000 | D35: -6254000 | E35: 407000 | F35: 4056 | G35: -1277 | H35: 6025 | I35: 3.285898 | J35: -112.55113 | K35: 399983 | M35: -7.9832971e-05 | N35: -0.0066667795 | O35: -0.00028010458 | P35: 0.0025838614 | Q35: 0.0012982264 | R35: -0.01064837 | AJ35: =NA() -> #N/A | AK35: 2 | AL35: 3 | AM35: =NA() -> #N/A | AN35: =NA() -> #N/A | AO35: =NA() -> #N/A | AP35: =NA() -> #N/A
A36: 2.0638709e+08 | C36: -2544000 | D36: -6254000 | E36: 408400 | F36: 4057 | G36: -1275 | H36: 6025 | I36: 3.285898 | J36: -112.55113 | K36: 399983 | M36: -0.00056680292 | N36: 0.0070184469 | O36: 0.0013518706 | P36: 0.0020593405 | Q36: 0.0011992827 | R36: -0.010696054 | AJ36: =NA() -> #N/A | AK36: 2 | AL36: 3 | AM36: =NA() -> #N/A | AN36: =NA() -> #N/A | AO36: =NA() -> #N/A | AP36: =NA() -> #N/A
A37: 2.0638709e+08 | C37: -2539000 | D37: -6255000 | E37: 409900 | F37: 4058 | G37: -1274 | H37: 6025 | I37: 3.285898 | J37: -112.55113 | K37: 399983 | M37: -5.5991113e-05 | N37: -0.00859797 | O37: -0.00053044409 | P37: 0.0020593405 | Q37: 0.0011122599 | R37: -0.009766221 | AJ37: =NA() -> #N/A | AK37: 2 | AL37: 3 | AM37: =NA() -> #N/A | AN37: =NA() -> #N/A | AO37: =NA() -> #N/A | AP37: =NA() -> #N/A
A38: 2.0638709e+08 | C38: -2534000 | D38: -6255000 | E38: 411400 | F38: 4058 | G38: -1272 | H38: 6025 | I38: 3.285898 | J38: -112.55113 | K38: 399983 | M38: -0.00063594431 | N38: 0.0082582235 | O38: 0.0014162436 | P38: 0.0015825033 | Q38: 0.0010013953 | R38: -0.0091463327 | AJ38: =NA() -> #N/A | AK38: 2 | AL38: 3 | AM38: =NA() -> #N/A | AN38: =NA() -> #N/A | AO38: =NA() -> #N/A | AP38: =NA() -> #N/A
A39: 2.0638709e+08 | C39: -2529000 | D39: -6255000 | E39: 411400 | F39: 4058 | G39: -1272 | H39: 6025 | I39: 3.5150177 | J39: -112.39127 | K39: 399975.69 | M39: -1.7844141e-05 | N39: -0.0076442957 | O39: -0.00043865293 | P39: 0.0022500753 | Q39: 0.0012231246 | R39: -0.0092178583 | AJ39: 1 | AK39: =NA() -> #N/A | AL39: 3 | AM39: =NA() -> #N/A | AN39: =NA() -> #N/A | AO39: =NA() -> #N/A | AP39: =NA() -> #N/A
A40: 2.0638709e+08 | C40: -2524000 | D40: -6256000 | E40: 415900 | F40: 4061 | G40: -1266 | H40: 6024 | I40: 3.5150177 | J40: -112.39127 | K40: 399975.69 | M40: -0.00069376081 | N40: 0.009354949 | O40: 0.0015414134 | P40: 0.0020593405 | Q40: 0.0012946501 | R40: -0.009265542 | AJ40: =NA() -> #N/A | AK40: =NA() -> #N/A | AL40: =NA() -> #N/A | AM40: =NA() -> #N/A | AN40: =NA() -> #N/A | AO40: =NA() -> #N/A | AP40: =NA() -> #N/A
A41: 2.0638709e+08 | C41: -2519000 | D41: -6256000 | E41: 417400 | F41: 4062 | G41: -1264 | H41: 6024 | I41: 3.5150177 | J41: -112.39127 | K41: 399975.69 | M41: 1.0766089e-05 | N41: -0.0065714121 | O41: -0.00034209341 | P41: 0.0020116568 | Q41: 0.0011444464 | R41: -0.0083118677 | AJ41: =NA() -> #N/A | AK41: 2 | AL41: 3 | AM41: =NA() -> #N/A | AN41: =NA() -> #N/A | AO41: =NA() -> #N/A | AP41: =NA() -> #N/A
A42: 2.0638709e+08 | C42: -2514000 | D42: -6257000 | E42: 418900 | F42: 4062 | G42: -1263 | H42: 6024 | I42: 3.5150177 | J42: -112.39127 | K42: 399975.69 | M42: -0.00050719827 | N42: 0.0070661306 | O42: 0.0011861697 | P42: 0.0015825033 | Q42: 0.0010502711 | R42: -0.0076919794 | AJ42: =NA() -> #N/A | AK42: 2 | AL42: 3 | AM42: =NA() -> #N/A | AN42: =NA() -> #N/A | AO42: =NA() -> #N/A | AP42: =NA() -> #N/A
A43: 2.0638709e+08 | C43: -2509000 | D43: -6277000 | E43: 420400 | F43: 4063 | G43: -1261 | H43: 6024 | I43: 3.5150177 | J43: -112.39127 | K43: 399975.69 | M43: 3.8184226e-05 | N43: -0.0076204538 | O43: -0.00048991293 | P43: 0.001630187 | Q43: 0.00097278506 | R43: -0.0074058771 | AJ43: =NA() -> #N/A | AK43: 2 | AL43: 3 | AM43: =NA() -> #N/A | AN43: =NA() -> #N/A | AO43: =NA() -> #N/A | AP43: =NA() -> #N/A
...

Sheet Sheet1
A1: Eroare inserată | B1: Interval de timp aproximativ în grafic [s] | C1: Observație
A2: Salt de poziție / modificare ECEF | B2: 72.61 – 73.86 | C2: Coordonatele ECEF au fost modificate brusc, producând discontinuități în poziție.
A3: Salt de poziție / modificare ECEF | B3: 74.61 – 75.12 | C3: A fost introdusă o altă modificare punctuală în coordonatele ECEF.
A4: Salt de timp GNSS | B4: 83.62 – 85.37 | C4: Au fost modificate câmpurile de timp GNSS, inclusiv GPS_SECONDS și GPS_WEEKS.
A5: Eroare de heading | B5: 89.64 – 93.14 | C5: Au fost modificate valorile de latitudine și longitudine pentru a produce o schimbare de direcție necorelată cu IMU.
A6: Nepotrivire de viteză | B6: 105.41 – 114.43 | C6: Componentele vitezei GNSS au fost modificate, astfel încât viteza raportată să nu mai fie coerentă cu deplasarea.
A7: Poziție înghețată / altitudine modificată | B7: 139.46 – 145.72 | C7: Poziția a fost menținută aproape constantă, iar altitudinea a fost modificată pe intervale punctuale.
A8: Poziție înghețată / salt de poziție geografică | B8: 153.99 – 159.00 | C8: Latitudinea și longitudinea au fost menținute constante, apoi modificate brusc.
A9: Poziție înghețată / salt de poziție geografică | B9: 168.27 – 172.28 | C9: A fost introdusă o nouă zonă cu poziție constantă, urmată de modificare bruscă.
A10: Poziție înghețată / salt de poziție geografică | B10: 183.54 – 187.79 | C10: Poziția geografică a fost menținută constantă pe un interval, în timp ce celelalte câmpuri continuă să evolueze.
A11: GNSS stale / date indisponibile | B11: 197.56 – 223.87 | C11: Valorile GNSS au fost eliminate sau marcate ca indisponibile, rezultând o zonă fără date valide.
A12: Salt de poziție geografică | B12: 245.15 – 245.40 | C12: Latitudinea, longitudinea și altitudinea au fost schimbate brusc într-un interval scurt.
A13: Poziție înghețată / schimbare poziție | B13: 249.16 – 253.66 | C13: Poziția a fost menținută constantă, apoi modificată pentru a produce activarea flag-urilor asociate.
